{"uuid": "322de5b2-d206-4946-94c0-3b2003a67785", "children": ["a1af4991-1a36-4a3b-82a0-b4ba5c82e0b5"], "befores": [{"name": "refresh_web", "status": "passed", "start": 1658667892661, "stop": 1658667892661}], "afters": [{"name": "refresh_web::0", "status": "broken", "statusDetails": {"message": "urllib3.exceptions.MaxRetryError: HTTPConnectionPool(host='localhost', port=54612): Max retries exceeded with url: /session/acbd3fb61fccad3612417a322b259b91/refresh (Caused by NewConnectionError('<urllib3.connection.HTTPConnection object at 0x7fefb887f700>: Failed to establish a new connection: [Errno 61] Connection refused'))\n", "trace": "  File \"/Library/Frameworks/Python.framework/Versions/3.9/lib/python3.9/site-packages/allure_commons/_allure.py\", line 200, in __call__\n    return self._fixture_function(*args, **kwargs)\n  File \"/Library/Frameworks/Python.framework/Versions/3.9/lib/python3.9/site-packages/_pytest/fixtures.py\", line 899, in _teardown_yield_fixture\n    next(it)\n  File \"/Users/wepie/Desktop/class_webtest/Testcase/conftest.py\", line 37, in refresh_web\n    driver.refresh()\n  File \"/Library/Frameworks/Python.framework/Versions/3.9/lib/python3.9/site-packages/selenium/webdriver/remote/webdriver.py\", line 1062, in refresh\n    self.execute(Command.REFRESH)\n  File \"/Library/Frameworks/Python.framework/Versions/3.9/lib/python3.9/site-packages/selenium/webdriver/remote/webdriver.py\", line 423, in execute\n    response = self.command_executor.execute(driver_command, params)\n  File \"/Library/Frameworks/Python.framework/Versions/3.9/lib/python3.9/site-packages/selenium/webdriver/remote/remote_connection.py\", line 333, in execute\n    return self._request(command_info[0], url, body=data)\n  File \"/Library/Frameworks/Python.framework/Versions/3.9/lib/python3.9/site-packages/selenium/webdriver/remote/remote_connection.py\", line 355, in _request\n    resp = self._conn.request(method, url, body=body, headers=headers)\n  File \"/Library/Frameworks/Python.framework/Versions/3.9/lib/python3.9/site-packages/urllib3/request.py\", line 78, in request\n    return self.request_encode_body(\n  File \"/Library/Frameworks/Python.framework/Versions/3.9/lib/python3.9/site-packages/urllib3/request.py\", line 170, in request_encode_body\n    return self.urlopen(method, url, **extra_kw)\n  File \"/Library/Frameworks/Python.framework/Versions/3.9/lib/python3.9/site-packages/urllib3/poolmanager.py\", line 375, in urlopen\n    response = conn.urlopen(method, u.request_uri, **kw)\n  File \"/Library/Frameworks/Python.framework/Versions/3.9/lib/python3.9/site-packages/urllib3/connectionpool.py\", line 813, in urlopen\n    return self.urlopen(\n  File \"/Library/Frameworks/Python.framework/Versions/3.9/lib/python3.9/site-packages/urllib3/connectionpool.py\", line 813, in urlopen\n    return self.urlopen(\n  File \"/Library/Frameworks/Python.framework/Versions/3.9/lib/python3.9/site-packages/urllib3/connectionpool.py\", line 813, in urlopen\n    return self.urlopen(\n  File \"/Library/Frameworks/Python.framework/Versions/3.9/lib/python3.9/site-packages/urllib3/connectionpool.py\", line 785, in urlopen\n    retries = retries.increment(\n  File \"/Library/Frameworks/Python.framework/Versions/3.9/lib/python3.9/site-packages/urllib3/util/retry.py\", line 592, in increment\n    raise MaxRetryError(_pool, url, error or ResponseError(cause))\n"}, "start": 1658667898937, "stop": 1658667898945}], "start": 1658667892661, "stop": 1658667898946}